Workbook

Sheet ADDDF
A1: ADDDF_balance-sheet_Annual_As_Originally_Reported | B1: 2019 | C1: 2020 | D1: 2021 | E1: 2022 | F1: 2023
A2: Total Assets | B2: 20680000000 | C2: 21053000000 | D2: 22137000000 | E2: 20296000000 | F2: 18020000000
A3: Total Current Assets | B3: 10934000000 | C3: 12154000000 | D3: 13944000000 | E3: 11732000000 | F3: 9809000000
A4: Cash, Cash Equivalents and Short Term Investments | B4: 2662000000 | C4: 4239000000 | D4: 3937000000 | E4: 966000000 | F4: 2220000000
A5: Cash and Cash Equivalents | B5: 2220000000 | C5: 3994000000 | D5: 3828000000 | E5: 798000000 | F5: 1431000000
A6: Short Term Investments | B6: 442000000 | C6: 245000000 | D6: 109000000 | E6: 168000000 | F6: 789000000
A7: Other Short Term Investments | B7: 442000000 | C7: 245000000 | D7: 109000000 | E7: 168000000 | F7: 789000000
A8: Inventories | B8: 4085000000 | C8: 4397000000 | D8: 4009000000 | E8: 5973000000 | F8: 4525000000
A9: Raw Materials, Consumables and Supplies | B9: 6000000 | C9: 8000000 | D9: 7000000 | E9: 9000000 | F9: 8000000
A10: Work-in-Process | B10: 0 | C10: 0 | D10: 0 | E10: 0 | F10: 0
A11: Finished Goods and Merchandise | B11: 4079000000 | C11: 4389000000 | D11: 4002000000 | E11: 5964000000 | F11: 4516000000
A12: Inventory Allowance/Adjustments
A13: Trade and Other Receivables, Current | B13: 3278000000 | C13: 2713000000 | D13: 3017000000 | E13: 3605000000 | F13: 2062000000
A14: Trade/Accounts Receivable, Current | B14: 2625000000 | C14: 1952000000 | D14: 2175000000 | E14: 2529000000 | F14: 1906000000
A15: Gross Trade/Accounts Receivable, Current | B15: 2814000000 | C15: 2219000000 | D15: 2383000000 | E15: 2759000000 | F15: 2135000000
A16: Allowance/Adjustments for Trade/Accounts Receivable, Current | B16: -189000000 | C16: -267000000 | D16: -208000000 | E16: -230000000 | F16: -229000000
A17: Taxes Receivable, Current | B17: 437000000 | C17: 510000000 | D17: 521000000 | E17: 734000000 | F17: 156000000
A18: Notes Receivable, Current | C18: 6000000 | D18: 12000000 | E18: 0
A19: Accrued Income/Unbilled Revenue/Cost in Excess of Billings, Current | B19: 17000000 | C19: 16000000 | D19: 46000000 | E19: 62000000
A20: Other Receivables, Current | B20: 199000000 | C20: 229000000 | D20: 263000000 | E20: 280000000
A21: Other Current Assets | B21: 425000000 | C21: 385000000 | D21: 356000000 | E21: 420000000 | F21: 1003000000
A22: Derivative Investment and Hedging Assets, Current | B22: 166000000 | C22: 185000000 | D22: 273000000 | E22: 232000000
A23: Prepayments and Deposits, Current | B23: 318000000 | C23: 240000000 | D23: 318000000 | E23: 296000000
A24: Deferred Costs/Assets, Current | E24: 241000000
A25: Assets Held for Sale/Discontinued Operations, Current | C25: 0 | D25: 2033000000 | E25: 0
A26: Total Non-Current Assets | B26: 9746000000 | C26: 8899000000 | D26: 8193000000 | E26: 8563000000 | F26: 8211000000
A27: Net Property, Plant and Equipment | B27: 5311000000 | C27: 4587000000 | D27: 4825000000 | E27: 4943000000 | F27: 4405000000
A28: Gross Property, Plant and Equipment | B28: 7336000000 | C28: 6756000000 | D28: 7141000000 | E28: 7571000000 | F28: 7112000000
A29: Properties | B29: 4627000000 | C29: 4169000000 | D29: 4586000000 | E29: 4890000000 | F29: 4495000000
A30: Land and Improvements | B30: 1842000000 | C30: 1852000000 | D30: 2093000000 | E30: 2290000000 | F30: 2300000000
A31: Leasehold and Improvements | B31: 2785000000 | C31: 2317000000 | D31: 2493000000 | E31: 2600000000 | F31: 2195000000
A32: Construction in Progress and Advance Payments | B32: 221000000 | C32: 258000000 | D32: 212000000 | E32: 230000000 | F32: 156000000
A33: Leased Property, Plant and Equipment | B33: 146000000 | C33: 113000000 | D33: 76000000 | E33: 65000000 | F33: 53000000
A34: Other Property, Plant and Equipment | B34: 2342000000 | C34: 2216000000 | D34: 2267000000 | E34: 2386000000 | F34: 2408000000
A35: Accumulated Depreciation and Impairment | B35: -2025000000 | C35: -2169000000 | D35: -2316000000 | E35: -2628000000 | F35: -2707000000
A36: Accumulated Depreciation | B36: -2025000000 | C36: -2169000000 | D36: -2316000000 | E36: -2628000000 | F36: -2707000000
A37: Accumulated Depreciation of Properties | B37: -520000000 | C37: -620000000 | D37: -704000000 | E37: -849000000 | F37: -922000000
... A45: Other Intangible Assets | B45: 305000000 | C45: 252000000 | D45: 1223000000 | E45: 1425000000 | F45: 442000000
A46: Trademarks and Patents | B46: 1412000000 | C46: 1295000000 | D46: 32000000
A47: Software and Technology | B47: 1086000000 | C47: 1107000000
...

Sheet Income Statement
A1: ADDDF_income-statement_Annual_As_Originally_Reported | B1: 2019 | C1: 2020 | D1: 2021 | E1: 2022 | F1: 2023
A2: Gross Profit | B2: 12293000000 | C2: 9854000000 | D2: 10765000000 | E2: 10644000000 | F2: 10183000000
A3: Total Revenue | B3: 23640000000 | C3: 19844000000 | D3: 21234000000 | E3: 22511000000 | F3: 21427000000
A4: Business Revenue | B4: 23640000000 | C4: 19844000000 | D4: 21234000000 | E4: 22511000000 | F4: 21427000000
A5: Cost of Revenue | B5: -11347000000 | C5: -9990000000 | D5: -10469000000 | E5: -11867000000 | F5: -11244000000
A6: Cost of Goods and Services | B6: -11347000000 | C6: -9990000000 | D6: -10469000000 | E6: -11867000000 | F6: -11244000000
A7: Operating Income/Expenses | B7: -9620000000 | C7: -8993000000 | D7: -8776000000 | E7: -9915000000 | F7: -9904000000
A8: Selling, General and Administrative Expenses | B8: -9691000000 | C8: -8996000000 | D8: -8810000000 | E8: -10015000000 | F8: -9914000000
A9: General and Administrative Expenses | B9: -1652000000 | C9: -1461000000 | D9: -1481000000 | E9: -1651000000 | F9: -1839000000
A10: Selling and Marketing Expenses | B10: -8039000000 | C10: -7535000000 | D10: -7329000000 | E10: -8364000000 | F10: -8075000000
A11: Provisions | B11: 9000000 | C11: 18000000 | D11: 14000000 | E11: 7000000 | F11: 7000000
A12: Other Provisions | B12: 9000000 | C12: 18000000 | D12: 14000000 | E12: 7000000 | F12: 7000000
A13: Other Income/Expense, Operating | B13: 62000000 | C13: -15000000 | D13: 20000000 | E13: 93000000 | F13: 3000000
... A15: Other Expenses, Operating | B15: -134000000 | C15: -119000000 | D15: -76000000 | E15: -182000000 | F15: -137000000
A16: Research and Development Expenses
A17: Total Operating Profit/Loss | B17: 2673000000 | C17: 861000000 | D17: 1989000000 | E17: 729000000 | F17: 279000000
A18: Non-Operating Income/Expense, Total | B18: -115000000 | C18: -286000000 | D18: -200000000 | E18: -341000000 | F18: -216000000
A19: Total Net Finance Income/Expense | B19: -97000000 | C19: -138000000 | D19: -162000000 | E19: -115000000 | F19: -83000000
A20: Net Interest Income/Expense | B20: -110000000 | C20: -139000000 | D20: -165000000 | E20: -114000000 | F20: -121000000
A21: Interest Expense Net of Capitalized Interest | B21: -160000000 | C21: -164000000 | D21: -177000000 | E21: -137000000 | F21: -160000000
A22: Interest Income | B22: 50000000 | C22: 25000000 | D22: 12000000 | E22: 23000000 | F22: 39000000
A23: Other Finance Income/Expenses | B23: 13000000 | C23: 1000000 | D23: 3000000 | E23: -1000000 | F23: 38000000
A24: Other Finance Income | B24: 14000000 | C24: 4000000 | D24: 7000000 | E24: 16000000 | F24: 40000000
A25: Other Finance Expenses | B25: -1000000 | C25: -3000000 | D25: -4000000 | E25: -17000000 | F25: -2000000
A26: Net Investment Income | B26: -5000000 | C26: -37000000 | D26: -37000000 | E26: -166000000 | F26: -121000000
A27: Gain/Loss on Foreign Currency Exchange | B27: -5000000 | C27: -37000000 | D27: -37000000 | E27: -166000000 | F27: -121000000
A28: Irregular Income/Expense | B28: -13000000 | C28: -111000000 | D28: -1000000 | E28: -60000000 | F28: -12000000
... A30: Write Off/Write Down of Other Assets | B30: -18000000 | C30: -114000000 | D30: -6000000 | E30: -63000000 | F30: -19000000
A31: Disposal of Businesses
A32: Impairment/Write Off/Write Down of Capital Assets
A33: Goodwill Impairment/Write Off
A34: Pretax Income | B34: 2558000000 | C34: 575000000 | D34: 1852000000 | E34: 388000000 | F34: 65000000
A35: Provision for Income Tax | B35: -640000000 | C35: -146000000 | D35: -360000000 | E35: -134000000 | F35: -124000000
A36: Net Income before Extraordinary Items and Discontinued Operations | B36: 1918000000 | C36: 429000000 | D36: 1492000000 | E36: 254000000 | F36: -58000000
A37: Discontinued Operations | B37: 59000000 | C37: 13000000 | D37: 666000000 | E37: 384000000 | F37: 44000000
A38: Net Income after Extraordinary Items and Discontinued Operations | B38: 1977000000 | C38: 443000000 | D38: 2158000000 | E38: 638000000 | F38: -14000000
A39: Non-Controlling/Minority Interests | B39: -2000000 | C39: -11000000 | D39: -42000000 | E39: -26000000 | F39: -61000000
A40: Net Income after Non-Controlling/Minority Interests | B40: 1976000000 | C40: 432000000 | D40: 2116000000 | E40: 612000000 | F40: -75000000
A41: Net Income Available to Common Stockholders | B41: 1976000000 | C41: 432000000 | D41: 2116000000 | E41: 612000000 | F41: -75000000
A42: Diluted Net Income Available to Common Stockholders | B42: 1976000000 | C42: 432000000 | D42: 2116000000 | E42: 612000000 | F42: -75000000
...

Sheet Cash Flow Statement
A1: ADDDF_cash-flow_Annual_As_Originally_Reported | B1: 2019 | C1: 2020 | D1: 2021 | E1: 2022 | F1: 2023 | G1: TTM
A2: Cash Flow from Operating Activities, Indirect | B2: 2819000000 | C2: 1486000000 | D2: 3192000000 | E2: -543000000 | F2: 2630000000 | G2: 2783000000
A3: Net Cash Flow from Continuing Operating Activities, Indirect | B3: 2828000000 | C3: 1489000000 | D3: 2873000000 | E3: -458000000 | F3: 2630000000 | G3: 2783000000
A4: Cash Generated from Operating Activities | B4: 3519000000 | C4: 1893000000 | D4: 3316000000 | E4: -34000000 | F4: 2938000000 | G4: 3015000000
A5: Income/Loss before Non-Cash Adjustment | B5: 2558000000 | C5: 575000000 | D5: 1852000000 | E5: 388000000 | F5: 65000000 | G5: 735000000
A6: Total Adjustments for Non-Cash Items | B6: 1209000000 | C6: 1568000000 | D6: 1283000000 | E6: 1579000000 | F6: 1449000000 | G6: 1422000000
A7: Depreciation, Amortization and Depletion, Non-Cash Adjustment | B7: 1214000000 | C7: 1370000000 | D7: 1149000000 | E7: 1375000000 | F7: 1212000000 | G7: 1180000000
A8: Depreciation and Amortization, Non-Cash Adjustment | B8: 1214000000 | C8: 1370000000 | D8: 1149000000 | E8: 1375000000 | F8: 1212000000 | G8: 1180000000
A9: Depreciation, Non-Cash Adjustment | F9: 1212000000
A10: Interest and Finance Income/Expenses, Non-Cash Adjustment | B10: 110000000 | C10: 139000000 | D10: 98000000 | E10: 115000000 | F10: 123000000 | G10: 130000000
A11: Net Investment Income/Loss, Non-Cash Adjustment | B11: -1000000 | C11: 35000000 | D11: 51000000 | E11: 85000000 | F11: 144000000 | G11: 117000000
A12: Net Foreign Currency Exchange Gain/Loss, Non-Cash Adjustment | B12: -1000000 | C12: 35000000 | D12: 51000000 | E12: 85000000 | F12: 144000000 | G12: 117000000
A13: Irregular Income/Loss, Non-Cash Adjustment | B13: 3000000 | C13: 22000000 | D13: -21000000 | E13: 12000000 | F13: -22000000 | G13: 22000000
A14: Gain/Loss on Disposals, Non-Cash Adjustment | B14: 11000000 | C14: 28000000 | D14: 13000000 | E14: 16000000 | F14: 20000000 | G14: 48000000
A15: Gain/Loss on Disposal/Sale of Fixed Assets, Non-Cash Adjustment | B15: 11000000 | C15: 28000000 | D15: 13000000 | E15: 16000000 | F15: 20000000 | G15: 48000000
A16: Write Down and Write off of Other Assets, Non-Cash Adjustment | B16: -8000000 | C16: -6000000 | D16: -34000000 | E16: -4000000 | F16: -42000000 | G16: -26000000
A17: Other Non-Cash Items | B17: -12000000 | C17: 2000000 | D17: 6000000 | E17: -8000000 | F17: -8000000 | G17: -27000000
A18: Pension and Employee Benefit Expense, Non-Cash Adjustment | B18: -105000000
A19: Changes in Operating Capital | B19: -248000000 | C19: -250000000 | D19: 181000000 | E19: -2000000000 | F19: 1424000000 | G19: 859000000
A20: Change in Inventories | B20: -505000000 | C20: -503000000 | D20: 125000000 | E20: -1901000000 | F20: 1297000000 | G20: 157000000
A21: Change in Trade and Other Receivables | B21: -694000000 | C21: 394000000 | D21: -170000000 | E21: -820000000 | F21: 995000000 | G21: -196000000
A22: Change in Payables and Accrued Expenses | B22: 951000000 | C22: -141000000 | D22: 226000000 | E22: 721000000 | F22: -868000000 | G22: 898000000
A23: Change in Trade and Other Payables | B23: 951000000 | C23: -141000000 | D23: 226000000 | E23: 721000000 | F23: -868000000 | G23: 898000000
A24: Change in Trade/Accounts Payable | B24: 951000000 | C24: -141000000 | D24: 226000000 | E24: 721000000 | F24: -868000000 | G24: 898000000
A25: Taxes Refund/Paid, Indirect | B25: -692000000 | C25: -404000000 | D25: -444000000 | E25: -424000000 | F25: -307000000 | G25: -255000000
A26: Interest Paid, CFO Indirect
A27: Net Cash Flow from Discontinuing Operating Activities | B27: -9000000 | C27: -3000000 | D27: 320000000 | E27: -85000000 | F27: 0
A28: Cash Flow from Investing Activities | B28: -925000000 | C28: -115000000 | D28: -424000000 | E28: 495000000 | F28: -450000000 | G28: -373000000
A29: Cash Flow from Continuing Investing Activities | B29: -927000000 | C29: -115000000 | D29: -414000000 | E29: 494000000 | F29: -450000000 | G29: -371000000
A30: Purchase/Sale and Disposal of Property, Plant and Equipment, Net | B30: -585000000 | C30: -362000000 | D30: -493000000 | E30: -503000000 | F30: -353000000 | G30: -375000000
A31: Purchase of Property, Plant and Equipment | B31: -598000000 | C31: -379000000 | D31: -494000000 | E31: -504000000 | F31: -363000000 | G31: -383000000
A32: Sale and Disposal of Property, Plant and Equipment | B32: 13000000 | C32: 17000000 | D32: 1000000 | E32: 1000000 | F32: 10000000 | G32: 8000000
A33: Purchase/Sale of Intangibles, Net | B33: -110000000 | C33: -60000000 | D33: -172000000 | E33: -190000000 | F33: -140000000 | G33: -125000000
A34: Purchase of Intangibles | B34: -110000000 | C34: -64000000 | D34: -173000000 | E34: -191000000 | F34: -141000000 | G34: -126000000
A35: Sale of Intangibles | B35: 0 | C35: 4000000 | D35: 1000000 | E35: 1000000 | F35: 1000000 | G35: 1000000
A36: Purchase/Sale of Business, Net | B36: 82000000 | C36: 42000000 | D36: 189000000 | E36: 1177000000 | F36: -19000000 | G36: 100000000
A37: Purchase/Acquisition of Business | F37: -19000000 | G37: 0
A38: Sale of Business | B38: 82000000 | C38: 42000000 | D38: 189000000 | E38: 1177000000 | F38: 0 | G38: 100000000
A39: Purchase/Sale of Investments, Net | B39: -364000000 | C39: 240000000 | D39: 49000000 | E39: -13000000 | F39: 23000000 | G39: -26000000
A40: Purchase of Investments | B40: -364000000 | C40: -49000000 | F40: -34000000
...

Sheet Competitors
A1: ` | K1: Under Armour | V1: Puma
A2: `
A3: NKE_income-statement_Annual_As_Originally_Reported | B3: 2019 | C3: 2020 | D3: 2021 | E3: 2022 | F3: 2023 | K3: UAA_income-statement_Annual_As_Originally_Reported | L3: 2019 | M3: 2020 | N3: 2021 | O3: 2022 | P3: 2023 | V3: PUM_income-statement_Annual_As_Originally_Reported | W3: 2019 | X3: 2020 | Y3: 2021 | Z3: 2022 | AA3: 2023
A4: Gross Profit | B4: 17474000000 | C4: 16241000000 | D4: 19962000000 | E4: 21479000000 | F4: 22292000000 | K4: Gross Profit | L4: 2470533000 | M4: 2160095000 | N4: 2861499000 | O4: 2649340000 | P4: 2630253000 | V4: Gross Profit | W4: 2686400000 | X4: 2458000000 | Y4: 3257800000 | Z4: 3902700000 | AA4: 3986600000
A5: Total Revenue | B5: 39117000000 | C5: 37403000000 | D5: 44538000000 | E5: 46710000000 | F5: 51217000000 | K5: Total Revenue | L5: 5267132000 | M5: 4474667000 | N5: 5683466000 | O5: 5903636000 | P5: 5701879000 | V5: Total Revenue | W5: 5502200000 | X5: 5234400000 | Y5: 6805400000 | Z5: 8465100000 | AA5: 8601700000
A6: Business Revenue | B6: 39117000000 | C6: 37403000000 | D6: 44538000000 | E6: 46710000000 | F6: 51217000000 | K6: Business Revenue | L6: 5267132000 | M6: 4474667000 | N6: 5683466000 | O6: 5903636000 | P6: 5701879000 | V6: Business Revenue | W6: 5502200000 | X6: 5234400000 | Y6: 6805400000 | Z6: 8465100000 | AA6: 8601700000
A7: Cost of Revenue | B7: -21643000000 | C7: -21162000000 | D7: -24576000000 | E7: -25231000000 | F7: -28925000000 | K7: Cost of Revenue | L7: -2796599000 | M7: -2314572000 | N7: -2821967000 | O7: -3254296000 | P7: -3071626000 | V7: Cost of Revenue | W7: -2815800000 | X7: -2776400000 | Y7: -3547600000 | Z7: -4562300000 | AA7: -4615100000
A8: Cost of Goods and Services | B8: -21643000000 | C8: -21162000000 | D8: -24576000000 | E8: -25231000000 | F8: -28925000000 | K8: Cost of Goods and Services | L8: -2796599000 | M8: -2314572000 | N8: -2821967000 | O8: -3254296000 | P8: -3071626000 | V8: Cost of Goods and Services | W8: -2815800000 | X8: -2776400000 | Y8: -3547600000 | Z8: -4552100000 | AA8: -4615100000
A9: Operating Income/Expenses | B9: -12702000000 | C9: -13126000000 | D9: -13025000000 | E9: -14804000000 | F9: -16377000000 | K9: Operating Income/Expenses | L9: -2233763000 | M9: -2171934000 | N9: -2334691000 | O9: -2365529000 | P9: -2400502000 | V9: Staff Cost, Cost of Revenue | Z9: -10200000
A10: Selling, General and Administrative Expenses | B10: -12702000000 | C10: -13126000000 | D10: -13025000000 | E10: -14804000000 | F10: -16377000000 | K10: Selling, General and Administrative Expenses | L10: -2233763000 | M10: -2171934000 | N10: -2334691000 | O10: -2365529000 | P10: -2400502000 | V10: Operating Income/Expenses | W10: -2250300000 | X10: -2249200000 | Y10: -2703200000 | Z10: -3262200000 | AA10: -3365100000
A11: General and Administrative Expenses | B11: -8949000000 | C11: -9534000000 | D11: -9911000000 | E11: -10954000000 | F11: -12317000000 | K11: Total Operating Profit/Loss | L11: 236770000 | M11: -11839000 | N11: 526808000 | O11: 283811000 | P11: 229751000 | V11: Selling, General and Administrative Expenses | W11: -2213800000 | X11: -2208700000 | Y11: -2665400000 | Z11: -3213900000 | AA11: -3332400000
A12: Selling and Marketing Expenses | B12: -3753000000 | C12: -3592000000 | D12: -3114000000 | E12: -3850000000 | F12: -4060000000 | K12: Non-Operating Income/Expense, Total | L12: -26928000 | M12: -480705000 | N12: -135931000 | O12: 3954000 | P12: 32323000 | V12: General and Administrative Expenses | W12: -340000000 | X12: -368700000 | Y12: -405200000 | Z12: -465800000 | AA12: -450900000
A13: Total Operating Profit/Loss | B13: 4772000000 | C13: 3115000000 | D13: 6937000000 | E13: 6675000000 | F13: 5915000000 | K13: Total Net Finance Income/Expense | L13: -21240000 | M13: -47259000 | N13: -44300000 | O13: -12826000 | P13: 268000 | V13: Selling and Marketing Expenses | W13: -1873800000 | X13: -1840000000 | Y13: -2260200000 | Z13: -2748100000 | AA13: -2881500000
A14: Non-Operating Income/Expense, Total | B14: 29000000 | C14: -228000000 | D14: -276000000 | E14: -24000000 | F14: 286000000 | K14: Net Interest Income/Expense | L14: -21240000 | M14: -47259000 | N14: -44300000 | O14: -12826000 | P14: -268000 | V14: Research and Development Expenses | W14: -61700000 | X14: -56600000 | Y14: -61700000 | Z14: -82200000 | AA14: -89000000
A15: Total Net Finance Income/Expense | B15: -49000000 | C15: -89000000 | D15: -262000000 | E15: -205000000 | F15: 6000000 | K15: Interest Expense Net of Capitalized Interest | L15: -21240000 | M15: -47259000 | V15: Other Income/Expense, Operating | W15: 25200000 | X15: 16100000 | Y15: 23900000 | Z15: 33900000 | AA15: 56300000
A16: Net Interest Income/Expense | B16: -49000000 | C16: -89000000 | D16: -262000000 | E16: -205000000 | F16: -6000000 | K16: Irregular Income/Expense | L16: . | M16: -601599000 | N16: -40518000 | O16: . | P16: . | V16: Other Income, Operating | W16: 25200000 | X16: 16100000 | Y16: 23900000 | Z16: 33900000 | AA16: 56300000
A17: Other Income/Expense, Non-Operating | B17: 78000000 | C17: -139000000 | D17: -14000000 | E17: 181000000 | F17: 280000000 | K17: Restructuring and Reorganization Income/Expense | L17: . | M17: -601599000 | N17: -33947000 | O17: . | P17: . | V17: Total Operating Profit/Loss | W17: 436100000 | X17: 208800000 | Y17: 554600000 | Z17: 640500000 | AA17: 621500000
A18: Pretax Income | B18: 4801000000 | C18: 2887000000 | D18: 6661000000 | E18: 6651000000 | F18: 6201000000 | K18: Impairment/Write Off/Write Down of Capital Assets | N18: -4750000 | V18: Non-Operating Income/Expense, Total | W18: -18500000 | X18: -46500000 | Y18: -49100000 | Z18: -88900000 | AA18: -143400000
A19: Provision for Income Tax | B19: -772000000 | C19: -348000000 | D19: -934000000 | E19: -605000000 | F19: -1131000000 | K19: Write Off/Write Down of Other Assets | N19: -1821000 | V19: Total Net Finance Income/Expense | W19: -33100000 | X19: -43000000 | Y19: -42700000 | Z19: -58900000 | AA19: -50300000
A20: Net Income before Extraordinary Items and Discontinued Operations | B20: 4029000000 | C20: 2539000000 | D20: 5727000000 | E20: 6046000000 | F20: 5070000000 | K20: Merger and Acquisition Income/Expense | V20: Net Interest Income/Expense | W20: -32400000 | X20: -42500000 | Y20: -42200000 | Z20: -44300000 | AA20: -45300000
A21: Net Income after Extraordinary Items and Discontinued Operations | B21: 4029000000 | C21: 2539000000 | D21: 5727000000 | E21: 6046000000 | F21: 5070000000 | K21: Other Income/Expense, Non-Operating | L21: -5688000 | M21: 168153000 | N21: -51113000 | O21: 16780000 | P21: 32055000 | V21: Interest Expense Net of Capitalized Interest | W21: -47800000 | X21: -77900000 | Y21: -72100000 | Z21: -123700000 | AA21: -158000000
A22: Net Income after Non-Controlling/Minority Interests | B22: 4029000000 | C22: 2539000000 | D22: 5727000000 | E22: 6046000000 | F22: 5070000000 | K22: Pretax Income | L22: 209842000 | M22: -492544000 | N22: 390877000 | O22: 287765000 | P22: 262074000 | V22: Interest Income | W22: 15400000 | X22: 35400000 | Y22: 29900000 | Z22: 79400000 | AA22: 112700000
A23: Net Income Available to Common Stockholders | B23: 4029000000 | C23: 2539000000 | D23: 5727000000 | E23: 6046000000 | F23: 5070000000 | K23: Provision for Income Tax | L23: -70024000 | M23: -49387000 | N23: -32072000 | O23: 101046000 | P23: -30006000 | V23: Other Finance Income/Expenses | W23: -700000 | X23: -500000 | Y23: -500000 | Z23: -14600000 | AA23: -5000000
A24: Diluted Net Income Available to Common Stockholders | B24: 4029000000 | C24: 2539000000 | D24: 5727000000 | E24: 6046000000 | F24: 5070000000 | K24: Earnings from Equity Interest | L24: -47679000 | M24: -7246000 | N24: 1255000 | O24: -2042000 | P24: -26000 | V24: Other Finance Expenses | W24: -700000 | X24: -500000 | Y24: -500000 | Z24: -14600000 | AA24: -5000000
A25: Income Statement Supplemental Section | K25: Net Income before Extraordinary Items and Discontinued Operations | L25: 92139000 | M25: -549177000 | N25: 360060000 | O25: 386769000 | P25: 232042000 | V25: Other Finance Income
A26: Reported Normalized and Operating Income/Expense Supplemental Section | K26: Net Income after Extraordinary Items and Discontinued Operations | L26: 92139000 | M26: -549177000 | N26: 360060000 | O26: 386769000 | P26: 232042000 | V26: Net Investment Income | W26: 10500000 | X26: -3900000 | Y26: -9000000 | Z26: -2200000 | AA26: -69400000
A27: Total Revenue as Reported, Supplemental | B27: 39117000000 | C27: 37403000000 | D27: 44538000000 | E27: 46710000000 | F27: 51217000000 | K27: Net Income after Non-Controlling/Minority Interests | L27: 92139000 | M27: -549177000 | N27: 360060000 | O27: 386769000 | P27: 232042000 | V27: Gain/Loss on Foreign Currency Exchange | W27: 10200000 | X27: -3900000 | Y27: -9000000 | Z27: -2200000 | AA27: -69400000
A28: Reported Effective Tax Rate | B28: 0.16 | C28: 0.12 | D28: 0.14 | E28: 0.09 | F28: 0.18 | K28: Net Income Available to Common Stockholders | L28: 92139000 | M28: -549177000 | N28: 360060000 | O28: 386769000 | P28: 232042000 | V28: Dividend and Investment Income | W28: 300000 | X28: .
A29: Discontinued Operations | K29: Dilution to Earnings | O29: 899000 | P29: 901000 | V29: Income from Associates, JointVentures and Other Participating Interests | W29: .
A30: Basic EPS | B30: 2.55 | C30: 1.63 | D30: 3.64 | E30: 3.83 | F30: 3.27 | K30: Diluted Net Income Available to Common Stockholders | L30: 92139000 | M30: -549177000 | N30: 360060000 | O30: 387668000 | P30: 232943000 | V30: Share of Profit and Interest from Associates | W30: .
A31: Basic EPS from Continuing Operations | B31: 2.55 | C31: 1.63 | D31: 3.64 | E31: 3.83 | F31: 3.27 | K31: Income Statement Supplemental Section | V31: Irregular Income/Expense | W31: 4100000 | X31: 400000 | Y31: 2600000 | Z31: -27800000 | AA31: -23700000
A32: Basic EPS from Discontinued Operations | K32: Reported Normalized and Operating Income/Expense Supplemental Section | V32: Other Irregular Income/Expense | W32: 2100000 | Z32: -27800000 | AA32: -23700000
A33: Diluted EPS | B33: 2.49 | C33: 1.6 | D33: 3.56 | E33: 3.75 | F33: 3.23 | K33: Total Revenue as Reported, Supplemental | L33: 5267132000 | M33: 4474667000 | N33: 5683466000 | O33: 5903636000 | P33: 5701879000 | V33: Fixed Asset Disposals | W33: 2000000 | X33: 400000 | Y33: 2600000
A34: Diluted EPS from Continuing Operations | B34: 2.49 | C34: 1.6 | D34: 3.56 | E34: 3.75 | F34: 3.23 | K34: Reported Total Operating Profit/Loss | L34: 236770000 | M34: -613438000 | N34: 486290000 | O34: 283811000 | P34: 229751000 | V34: Pretax Income | W34: 417600000 | X34: 162300000 | Y34: 505300000 | Z34: 551700000 | AA34: 478300000
A35: Diluted EPS from Discontinued Operations | K35: Reported Normalized Income | M35: -120172000 | N35: 396903000 | O35: 266327000 | P35: 244829000 | V35: Provision for Income Tax | W35: -108600000 | X35: -39200000 | Y35: -128500000 | Z35: -127400000 | AA35: -117800000
A36: Basic Weighted Average Shares Outstanding | B36: 1579700000 | C36: 1591600000 | D36: 1573000000 | E36: 1578800000 | F36: 1551600000 | K36: Reported Effective Tax Rate | L36: 0.33 | M36: -0.1 | N36: 0.08 | O36: -0.35 | P36: 0.11 | V36: Net Income before Extraordinary Items and Discontinued Operations | W36: 309000000 | X36: 123100000 | Y36: 376800000 | Z36: 424300000 | AA36: 360500000
A37: Diluted Weighted Average Shares Outstanding | B37: 1618400000 | C37: 1591600000 | D37: 1609400000 | E37: 1610800000 | F37: 1569800000 | K37: Reported Normalized Operating Profit | M37: 537000 | N37: 527323000 | O37: 303811000 | P37: 309751000 | V37: Net Income after Extraordinary Items and Discontinued Operations | W37: 309000000 | X37: 123100000 | Y37: 376800000 | Z37: 424400000 | AA37: 360600000
A38: Reported Normalized Diluted EPS | K38: Other Adjustments to Net Income Available to Common Stockholders | V38: Non-Controlling/Minority Interests | W38: -46600000 | X38: -44200000 | Y38: -67200000 | Z38: -70900000 | AA38: -55700000
A39: Total Dividend Per Share | B39: 0.86 | C39: 0.95 | D39: 1.07 | E39: 1.19 | F39: 1.32 | K39: Basic EPS | L39: 0.2 | M39: -1.21 | N39: 0.77 | O39: 0.86 | P39: 0.53 | V39: Net Income after Non-Controlling/Minority Interests | W39: 262400000 | X39: 78900000 | Y39: 309600000 | Z39: 353500000 | AA39: 304900000
A40: Regular Dividend Per Share Calc | B40: 0.86 | C40: 0.95 | D40: 1.07 | E40: 1.19 | F40: 1.32 | K40: Basic EPS from Continuing Operations | L40: 0.2 | M40: -1.21 | N40: 0.77 | O40: 0.86 | P40: 0.53 | V40: Net Income Available to Common Stockholders | W40: 262400000 | X40: 78900000 | Y40: 309600000 | Z40: 353500000 | AA40: 304900000
...

Sheet Ratios
B2: Adidas
B3: Ratio | C3: 2019 | D3: 2020 | E3: 2021 | F3: 2022 | G3: 2023 | H3: Significance
B4: Debt to Equity Ratio | C4: =ADDDF!B73/ADDDF!B125 -> 1.9304237 | D4: =ADDDF!C73/ADDDF!C125 -> 2.1464654 | E4: =ADDDF!D73/ADDDF!D125 -> 1.8246778 | F4: =ADDDF!E73/ADDDF!E125 -> 2.7929359 | G4: =ADDDF!F73/ADDDF!F125 -> 2.6588832 | H4: Indicates the proportion of financing from debt versus equity
B5: Short-Term vs. Long-Term Debt | C5: =ADDDF!B74/ADDDF!B101 -> 1.7979051 | D5: =ADDDF!C74/ADDDF!C101 -> 1.5947606 | E5: =ADDDF!D74/ADDDF!D101 -> 1.6804124 | F5: =ADDDF!E74/ADDDF!E101 -> 1.6274613 | G5: =ADDDF!F74/ADDDF!F101 -> 1.5920428 | H5: Evaluate company´s debt maturity profile
B6: Current Ratio | C6: =ADDDF!B3/ADDDF!B74 -> 1.249029 | D6: =ADDDF!C3/ADDDF!C74 -> 1.3769117 | E6: =ADDDF!D3/ADDDF!D74 -> 1.555382 | F6: =ADDDF!E3/ADDDF!E74 -> 1.2673652 | G6: =ADDDF!F3/ADDDF!F74 -> 1.2195698 | H6: indicates short-term liquidity
B7: Debt to Asset Ratio | C7: =ADDDF!B73/ADDDF!B2 -> 0.65875242 | D7: =ADDDF!C73/ADDDF!C2 -> 0.68218306 | E7: =ADDDF!D73/ADDDF!D2 -> 0.64597732 | F7: =ADDDF!E73/ADDDF!E2 -> 0.73635199 | G7: =ADDDF!F73/ADDDF!F2 -> 0.72669256 | H7: Shows the percentage of total assets financed by debt
B8: Net Debt-to-EBITDA Ratio | C8: =(ADDDF!B73-ADDDF!B5)/'Income Statement'!B48 -> 2.9656697 | D8: =(ADDDF!C73-ADDDF!C5)/'Income Statement'!C48 -> 4.987013 | E8: =(ADDDF!D73-ADDDF!D5)/'Income Statement'!D48 -> 3.4155251 | F8: =(ADDDF!E73-ADDDF!E5)/'Income Statement'!E48 -> 7.5490928 | G8: =(ADDDF!F73-ADDDF!F5)/'Income Statement'!F48 -> 8.5891016 | H8: Measures the company’s leverage relative to its operational cash flow.
B9: Return on Equity (ROE) | C9: ='Income Statement'!B42/ADDDF!B125 -> 0.28000567 | D9: ='Income Statement'!C42/ADDDF!C125 -> 0.06456434 | E9: ='Income Statement'!D42/ADDDF!D125 -> 0.27000128 | F9: ='Income Statement'!E42/ADDDF!E125 -> 0.11437115 | G9: ='Income Statement'!F42/ADDDF!F125 -> -0.015228426 | H9: Indicates how efficiently the company generates profit from shareholders’ investments.
B10: EBITDA Margin | C10: ='Income Statement'!B48/'Income Statement'!B3 -> 0.16264805 | D10: ='Income Statement'!C48/'Income Statement'!C3 -> 0.10476718 | E10: ='Income Statement'!D48/'Income Statement'!D3 -> 0.14439107 | F10: ='Income Statement'!E48/'Income Statement'!E3 -> 0.08324819 | G10: ='Income Statement'!F48/'Income Statement'!F3 -> 0.063377981 | H10: Shows operational profitability before accounting for interest, taxes, and depreciation.
B11: EBIT Interest Coverage Ratio | C11: ='Income Statement'!B85/'Cash Flow Statement'!B64*-1 -> 18.134615 | D11: ='Income Statement'!C85/'Cash Flow Statement'!C64*-1 -> 6.4840764 | E11: ='Income Statement'!D85/'Cash Flow Statement'!D64*-1 -> 18.918919 | F11: ='Income Statement'!E85/'Cash Flow Statement'!E64*-1 -> 6.2071429 | G11: ='Income Statement'!F85/'Cash Flow Statement'!F64*-1 -> 2.7116564 | H11: Indicates the company’s ability to pay interest on its debt.
B12: Quick Ratio | C12: =(ADDDF!B3-ADDDF!B8)/ADDDF!B74 -> 0.7823852 | D12: =(ADDDF!C3-ADDDF!C8)/ADDDF!C74 -> 0.87878101 | E12: =(ADDDF!D3-ADDDF!D8)/ADDDF!D74 -> 1.1081985 | F12: =(ADDDF!E3-ADDDF!E8)/ADDDF!E74 -> 0.6221238 | G12: =(ADDDF!F3-ADDDF!F8)/ADDDF!F74 -> 0.65696879 | H12: Focuses on liquid assets available to meet short-term obligations.
B13: Cash Flow-to-Debt Ratio | C13: ='Cash Flow Statement'!B2/ADDDF!B73 -> 0.20692946 | D13: ='Cash Flow Statement'!C2/ADDDF!C73 -> 0.10346748 | E13: ='Cash Flow Statement'!D2/ADDDF!D73 -> 0.22321678 | F13: ='Cash Flow Statement'!E2/ADDDF!E73 -> -0.036333222 | G13: ='Cash Flow Statement'!F2/ADDDF!F73 -> 0.20084002 | H13: Indicates how quickly the company can pay off debt with its operating cash flow.
B14: Free Cash Flow-to-Debt Ratio | C14: =('Cash Flow Statement'!B2-'Cash Flow Statement'!B31)/ADDDF!B73 -> 0.25082581 | D14: =('Cash Flow Statement'!C2-'Cash Flow Statement'!C31)/ADDDF!C73 -> 0.12985657 | E14: =('Cash Flow Statement'!D2-'Cash Flow Statement'!D31)/ADDDF!D73 -> 0.25776224 | F14: =('Cash Flow Statement'!E2-'Cash Flow Statement'!E31)/ADDDF!E73 -> -0.0026095684 | G14: =('Cash Flow Statement'!F2-'Cash Flow Statement'!F31)/ADDDF!F73 -> 0.22856052 | H14: Shows cash available for debt repayment after capital expenditures.
I19: 5 year
B20: Debt to Equity Ratio Comparison | I20: For all Company combine | J20: Adidas | M20: Metrics | N20: Adidas | O20: All Companies Combained
B21: Comapany Name | C21: 2019 | D21: 2020 | E21: 2021 | F21: 2022 | G21: 2023 | I21: =AVERAGE(C22:G25) -> 1.8058237 | J21: =AVERAGE(C22:G22) -> 2.2706772 | K21: Mean | M21: Mean | N21: =AVERAGE(C22:G22) -> 2.2706772 | O21: =AVERAGE(Table6[[2019]:[2023]]) -> 1.8058237
B22: Adidas | C22: =C4 -> 1.9304237 | D22: =D4 -> 2.1464654 | E22: =E4 -> 1.8246778 | F22: =F4 -> 2.7929359 | G22: =G4 -> 2.6588832 | I22: =MEDIAN(C22:G25) -> 1.6616068 | J22: =MEDIAN(C22:G22) -> 2.1464654 | K22: Median | M22: Median | N22: =MEDIAN(Table6[[#This Row],[2019]:[2023]]) -> 2.1464654 | O22: =MEDIAN(Table6[[2019]:[2023]]) -> 1.6616068
B23: Nike | C23: =Competitors!B155/Competitors!B185 -> 1.6235619 | D23: =Competitors!C155/Competitors!C185 -> 2.8909994 | E23: =Competitors!D155/Competitors!D185 -> 1.9560586 | F23: =Competitors!E155/Competitors!E185 -> 1.6386362 | G23: =Competitors!F155/Competitors!F185 -> 1.68002 | I23: =MODE(C22:G25) -> #N/A | J23: =MODE(C22:G22) -> #N/A | K23: Mode | M23: Minimum | N23: =MIN(C22:G22) -> 1.8246778 | O23: =MIN(Table6[[2019]:[2023]]) -> 1.2109158
B24: Under Armour | C24: =Competitors!L175/Competitors!L202 -> 1.252714 | D24: =Competitors!M175/Competitors!M202 -> 2.0015806 | E24: =Competitors!N175/Competitors!N202 -> 1.3893779 | F24: =Competitors!O175/Competitors!O202 -> 1.4304822 | G24: =Competitors!P175/Competitors!P202 -> 1.2109158 | I24: =MIN(C22:G25) -> 1.2109158 | J24: =MIN(C22:G22) -> 1.8246778 | K24: Minimum | M24: Maximum | N24: =MAX(C22:G22) -> 2.7929359 | O24: =MAX(Table6[[2019]:[2023]]) -> 2.8909994
B25: Puma | C25: =Competitors!W207/Competitors!W238 -> 1.2799563 | D25: =Competitors!X207/Competitors!X238 -> 1.655536 | E25: =Competitors!Y207/Competitors!Y238 -> 1.5140663 | F25: =Competitors!Z207/Competitors!Z238 -> 1.6676776 | G25: =Competitors!AA207/Competitors!AA238 -> 1.571506 | I25: =MAX(C22:G25) -> 2.8909994 | J25: =MAX(C22:G22) -> 2.7929359 | K25: Maximum
B28: EBIT Interest Coverage Ratio
B29: Comapany Name | C29: 2019 | D29: 2020 | E29: 2021 | F29: 2022 | G29: 2023
B30: Adidas | C30: =C11 -> 18.134615 | D30: =D11 -> 6.4840764 | E30: =E11 -> 18.918919 | F30: =F11 -> 6.2071429 | G30: =G11 -> 2.7116564
B31: Nike | C31: =Competitors!B46/Competitors!B110*-1 -> 32.379085 | D31: =Competitors!C46/Competitors!C110*-1 -> 21.621429 | E31: =Competitors!D46/Competitors!D110*-1 -> 23.733788 | F31: =Competitors!E46/Competitors!E110*-1 -> 23.934483 | G31: =Competitors!F46/Competitors!F110*-1 -> 18.870317
B32: Under Armour | C32: =Competitors!L51/Competitors!L125*-1 -> 14.131274 | D32: =Competitors!M51/Competitors!M125*-1 -> 0.58642493 | E32: =Competitors!N51/Competitors!N125*-1 -> 21.883533 | F32: =Competitors!O51/Competitors!O125*-1 -> 15.767978 | G32: =Competitors!P51/Competitors!P125*-1 -> 52.885953
B33: Puma | C33: =Competitors!W73/Competitors!W129*-1 -> 11.002294 | D33: =Competitors!X73/Competitors!X129*-1 -> 5.855814 | E33: =Competitors!Y73/Competitors!Y129*-1 -> 13.490991 | F33: =Competitors!Z73/Competitors!Z129*-1 -> 12.905204 | G33: =Competitors!AA73/Competitors!AA129*-1 -> 7.5906681
B36: Return on Capital (ROC)
B37: Comapany Name | C37: 2019 | D37: 2020 | E37: 2021 | F37: 2022 | G37: 2023
B38: Adidas | C38: ='Income Statement'!B85/(ADDDF!B73+ADDDF!B125) -> 0.13679884 | D38: ='Income Statement'!C85/(ADDDF!C73+ADDDF!C125) -> 0.048354154 | E38: ='Income Statement'!D85/(ADDDF!D73+ADDDF!D125) -> 0.094863803 | F38: ='Income Statement'!E85/(ADDDF!E73+ADDDF!E125) -> 0.042816318 | G38: ='Income Statement'!F85/(ADDDF!F73+ADDDF!F125) -> 0.024528302
B39: Nike | C39: =Competitors!B46/(Competitors!B185+Competitors!B155) -> 0.20887971 | D39: =Competitors!C46/(Competitors!C185+Competitors!C155) -> 0.096579669 | E39: =Competitors!D46/(Competitors!D185+Competitors!D155) -> 0.18426073 | F39: =Competitors!E46/(Competitors!E185+Competitors!E155) -> 0.17214355 | G39: =Competitors!F46/(Competitors!F185+Competitors!F155) -> 0.17446911
B40: Under Armour | C40: =Competitors!L51/(Competitors!L175+Competitors!L202) -> 0.052606456 | D40: =Competitors!M51/(Competitors!M175+Competitors!M202) -> 0.0033369591 | F40: =Competitors!O51/(Competitors!O175+Competitors!O202) -> 0.062389092 | G40: =Competitors!P51/(Competitors!P175+Competitors!P202) -> 0.049189684
B41: Puma | C41: =Competitors!W73/(Competitors!L175+Competitors!L202) -> 0.099039317 | D41: =Competitors!X73/(Competitors!M175+Competitors!M202) -> 0.050053393 | E41: =Competitors!Y73/(Competitors!N175+Competitors!N202) -> 0.12000651 | F41: =Competitors!Z73/(Competitors!O175+Competitors!O202) -> 0.14294588 | G41: =Competitors!AA73/(Competitors!P175+Competitors!P202) -> 0.15035497
B43: Operating Income / Sales
B44: Comapany Name | C44: 2019 | D44: 2020 | E44: 2021 | F44: 2022 | G44: 2023
B45: Adidas | C45: ='Income Statement'!B7/'Income Statement'!B3 -> -0.40693739 | D45: ='Income Statement'!C7/'Income Statement'!C3 -> -0.45318484 | E45: ='Income Statement'!D7/'Income Statement'!D3 -> -0.41329943 | F45: ='Income Statement'!E7/'Income Statement'!E3 -> -0.44045133 | G45: ='Income Statement'!F7/'Income Statement'!F3 -> -0.46222056
B46: Nike | C46: =Competitors!B13/Competitors!B5 -> 0.121993 | D46: =Competitors!C13/Competitors!C5 -> 0.08328209 | E46: =Competitors!D13/Competitors!D5 -> 0.15575464 | F46: =Competitors!E13/Competitors!E5 -> 0.14290302 | G46: =Competitors!F13/Competitors!F5 -> 0.115489
B47: Under Armour | C47: =Competitors!L9/Competitors!L5 -> -0.42409474 | D47: =Competitors!M9/Competitors!M5 -> -0.4853845 | E47: =Competitors!N9/Competitors!N5 -> -0.41078648 | F47: =Competitors!O9/Competitors!O5 -> -0.40069018 | G47: =Competitors!P9/Competitors!P5 -> -0.42100192
B48: Puma | C48: =Competitors!W10/Competitors!W5 -> -0.40898186 | D48: =Competitors!X10/Competitors!X5 -> -0.42969586 | E48: =Competitors!Y10/Competitors!Y5 -> -0.39721398 | F48: =Competitors!Z10/Competitors!Z5 -> -0.38537052 | G48: =Competitors!AA10/Competitors!AA5 -> -0.39121336
B50: Long-Term Debt / Capitalization
B51: Comapany Name | C51: 2019 | D51: 2020 | E51: 2021 | F51: 2022 | G51: 2023
...

Sheet Credit Rating
B2: Adidas
B3: Year | C3: S&P Rating | D3: S&P Outlook | E3: Moody's Rating | F3: Moody's Outlook
B4: 2020 | C4: N/A | D4: N/A | E4: N/A | F4: N/A
B5: 2020 | C5: A+ | D5: Stable | E5: A2 | F5: Stable
B6: 2021 | C6: A+ | D6: Stable | E6: A2 | F6: Stable
B7: 2022 | C7: A+ | D7: Negative | E7: A2 | F7: Negative
B8: 2023 | C8: A- | D8: Negative | E8: A3 | F8: Negative | G8: Treasury - adidas Annual Report 2023
G9: Ratings - adidas Group
B11: Nike
B12: Year | C12: S&P Rating | D12: S&P Outlook | E12: Moody's Rating | F12: Moody's Outlook
B13: 2019 | C13: AA- | D13: Stable | E13: A1 | F13: Stable
B14: 2020 | C14: AA- | D14: Stable | E14: A1 | F14: Negative
B15: 2021 | C15: AA- | D15: Stable | E15: A1 | F15: Negative
B16: 2022 | C16: AA- | D16: Stable | E16: A1 | F16: Stable
B17: 2023 | C17: AA- | D17: Stable | E17: A1 | F17: Stable
B21: Under Armour
B22: Year | C22: S&P Rating | D22: S&P Outlook | E22: Moody's Rating | F22: Moody's Outlook
B23: 2019 | C23: BB | D23: Stable | E23: Ba3 | F23: Stable
B24: 2020 | C24: BB | D24: Stable | E24: Ba3 | F24: Stable
B25: 2021 | C25: BB | D25: Stable | E25: Ba2 | F25: Positive
B26: 2022 | C26: BB | D26: Positive | E26: Ba2 | F26: Positive
B27: 2023 | C27: BB | D27: Stable | E27: Ba2 | F27: Stable
B31: Puma
B32: Year | C32: S&P Rating | D32: S&P Outlook | E32: Moody's Rating | F32: Moody's Outlook
B33: 2019 | C33: N/A | D33: N/A | E33: N/A | F33: N/A
B34: 2020 | C34: N/A | D34: N/A | E34: N/A | F34: N/A
B35: 2021 | C35: N/A | D35: N/A | E35: N/A | F35: N/A
B36: 2022 | C36: N/A | D36: N/A | E36: N/A | F36: N/A
B37: 2023 | C37: N/A | D37: N/A | E37: N/A | F37: N/A
B43: T Bond Rate | C43: 0.0248 | D43: German Rates & Bonds - Bloomberg
B44: Interest Coverage Ratio | C44: Rating | D44: Spread (%) | E44: Interest Rate (%)
B45: > 8.50 | C45: Aaa/AAA | D45: 0.004 | E45: =D45+$C$43 -> 0.0288 | I45: =2.72%+D45 -> 0.0312
B46: 6.5 –8.5 | C46: Aa2/AA | D46: 0.007 | E46: =D46+$C$43 -> 0.0318
B47: 5.5 –6.5 | C47: A1/A+ | D47: 0.0085 | E47: =D47+$C$43 -> 0.0333
B48: 4.25 –5.5 | C48: A2/A | D48: 0.01 | E48: =D48+$C$43 -> 0.0348
B49: 3 –4.25 | C49: A3/A- | D49: 0.013 | E49: =D49+$C$43 -> 0.0378
B50: 2.5 -3 | C50: Baa2/BBB | D50: 0.02 | E50: =D50+$C$43 -> 0.0448
B51: 2.25 –2.5 | C51: Ba1/BB+ | D51: 0.03 | E51: =D51+$C$43 -> 0.0548
B52: 2 –2.25 | C52: Ba2/BB | D52: 0.04 | E52: =D52+$C$43 -> 0.0648
B53: 1.75 -2 | C53: B1/B+ | D53: 0.055 | E53: =D53+$C$43 -> 0.0798
...

Sheet WACC Approach Nike
A1: Risk-Free Rate (Rf) | B1: 0.0396 | C1: T Bond Rate | D1: 10-year U.S. Treasury bond yield 1990-2023 | Statista
A2: Market Risk Premium (Rm - Rf) | B2: 0.057 | D2: https://www.statista.com/statistics/664840/average-market-risk-premium-usa
A3: Marginal Tax Rate | B3: =21%+7.6% -> 0.286 | C3: https://taxfoundation.org/data/all/state/state-corporate-income-tax-rates-brackets-2024/
A4: Levered Beta (βL) | B4: 1.03 | I4: adidas AG (ADS.DE) Stock Price, News, Quote & History - Yahoo Finance
A5: Unlevered Beta (βU) | B5: =Q6 -> 0.90107888 | P5: Step-2
A6: Total Debt (D) | B6: =Competitors!F155 -> 23527000000 | P6: Unlevered beta | Q6: =B4/(1+(1-B3)*(B6/B7)) -> 0.90107888
A7: Total Equity € | B7: =Dividend!O24*Competitors!F36 -> 117409572000 | C7: As of Dec 2023
A8: EBIT | B8: =Competitors!F46 -> 6548000000
A9: EBIT Interest Coverage Ratio | B9: =Ratios!G31 -> 18.870317
G10: Step-3
F11: Estimate Cost of Equity
E12: Debt to Capital Ratio | F12: D/E Ratio | G12: Levered Beta | H12: Cost of Equity
A13: =B6/(B6+B7) -> 0.16693325 | E13: 0 | F13: =E13/(1-E13) -> 0 | G13: =$Q$6*(1+(1-$B$3)*(F13)) -> 0.90107888 | H13: =$B$1+G13*$B$2 -> 0.090961496
E14: 0.1 | F14: =E14/(1-E14) -> 0.11111111 | G14: =$Q$6*(1+(1-$B$3)*(F14)) -> 0.97256447 | H14: =$B$1+G14*$B$2 -> 0.095036175
E15: 0.2 | F15: =E15/(1-E15) -> 0.25 | G15: =$Q$6*(1+(1-$B$3)*(F15)) -> 1.0619215 | H15: =$B$1+G15*$B$2 -> 0.10012952
E16: 0.3 | F16: =E16/(1-E16) -> 0.42857143 | G16: =$Q$6*(1+(1-$B$3)*(F16)) -> 1.176809 | H16: =$B$1+G16*$B$2 -> 0.10667811
E17: 0.4 | F17: =E17/(1-E17) -> 0.66666667 | G17: =$Q$6*(1+(1-$B$3)*(F17)) -> 1.3299924 | H17: =$B$1+G17*$B$2 -> 0.11540957
E18: 0.5 | F18: =E18/(1-E18) -> 1 | G18: =$Q$6*(1+(1-$B$3)*(F18)) -> 1.5444492 | H18: =$B$1+G18*$B$2 -> 0.1276336
E19: 0.6 | F19: =E19/(1-E19) -> 1.5 | G19: =$Q$6*(1+(1-$B$3)*(F19)) -> 1.8661344 | H19: =$B$1+G19*$B$2 -> 0.14596966
E20: 0.7 | F20: =E20/(1-E20) -> 2.3333333 | G20: =$Q$6*(1+(1-$B$3)*(F20)) -> 2.4022763 | H20: =$B$1+G20*$B$2 -> 0.17652975
E21: 0.8 | F21: =E21/(1-E21) -> 4 | G21: =$Q$6*(1+(1-$B$3)*(F21)) -> 3.4745602 | H21: =$B$1+G21*$B$2 -> 0.23764993
E22: 0.9 | F22: =E22/(1-E22) -> 9 | G22: =$Q$6*(1+(1-$B$3)*(F22)) -> 6.6914118 | H22: =$B$1+G22*$B$2 -> 0.42101047
E24: Pre-Tax Cost of Debt | F24: =B1 -> 0.0396
E25: Estimate Cost of Debts
D26: Debt to Capital Ratio | E26: D/E Ratio | F26: Debt | G26: EBIT | H26: Interest | I26: Pre-Tax Int. Cov | J26: Likely Rating | K26: Pre-Tax cost of debt | L26: Tax Rate | M26: After Tax Cost of Debt
D27: 0 | E27: =D27/(1-D27) -> 0 | F27: =$B$7*D27 -> 0 | G27: =$B$8 -> 6548000000 | H27: =F27*$F$24 -> 0 | I27: =G27/H27 -> #DIV/0! | J27: ='Credit Rating'!C45 -> Aaa/AAA | K27: =S42 -> 0.0436 | L27: =$B$3 -> 0.286 | M27: =K27*(1-L27) -> 0.0311304
D28: 0.1 | E28: =D28/(1-D28) -> 0.11111111 | F28: =$B$7*D28 -> 11740957200 | G28: =$B$8 -> 6548000000 | H28: =F28*$F$24 -> 4.6494191e+08 | I28: =G28/H28 -> 14.08348 | J28: =Q42 -> Aaa/AAA | K28: =S42 -> 0.0436 | L28: =$B$3 -> 0.286 | M28: =K28*(1-L28) -> 0.0311304
D29: 0.2 | E29: =D29/(1-D29) -> 0.25 | F29: =$B$7*D29 -> 23481914400 | G29: =$B$8 -> 6548000000 | H29: =F29*$F$24 -> 9.2988381e+08 | I29: =G29/H29 -> 7.04174 | J29: =Q43 -> Aa2/AA | K29: =S43 -> 0.0466 | L29: =$B$3 -> 0.286 | M29: =K29*(1-L29) -> 0.0332724
D30: 0.3 | E30: =D30/(1-D30) -> 0.42857143 | F30: =$B$7*D30 -> 35222871600 | G30: =$B$8 -> 6548000000 | H30: =F30*$F$24 -> 1.3948257e+09 | I30: =G30/H30 -> 4.6944933 | J30: =Q44 -> A1/A+ | K30: =S44 -> 0.0481 | L30: =$B$3 -> 0.286 | M30: =K30*(1-L30) -> 0.0343434
D31: 0.4 | E31: =D31/(1-D31) -> 0.66666667 | F31: =$B$7*D31 -> 46963828800 | G31: =$B$8 -> 6548000000 | H31: =F31*$F$24 -> 1.8597676e+09 | I31: =G31/H31 -> 3.52087 | J31: =Q46 -> A3/A- | K31: =S46 -> 0.0526 | L31: =$B$3 -> 0.286 | M31: =K31*(1-L31) -> 0.0375564
D32: 0.5 | E32: =D32/(1-D32) -> 1 | F32: =$B$7*D32 -> 58704786000 | G32: =$B$8 -> 6548000000 | H32: =F32*$F$24 -> 2.3247095e+09 | I32: =G32/H32 -> 2.816696 | J32: =Q46 -> A3/A- | K32: =S46 -> 0.0526 | L32: =$B$3 -> 0.286 | M32: =K32*(1-L32) -> 0.0375564
D33: 0.6 | E33: =D33/(1-D33) -> 1.5 | F33: =$B$7*D33 -> 70445743200 | G33: =$B$8 -> 6548000000 | H33: =F33*$F$24 -> 2.7896514e+09 | I33: =G33/H33 -> 2.3472467 | J33: =Q47 -> Baa2/BBB | K33: =S47 -> 0.0596 | L33: =$B$3 -> 0.286 | M33: =K33*(1-L33) -> 0.0425544
D34: 0.7 | E34: =D34/(1-D34) -> 2.3333333 | F34: =$B$7*D34 -> 82186700400 | G34: =$B$8 -> 6548000000 | H34: =F34*$F$24 -> 3.2545933e+09 | I34: =G34/H34 -> 2.0119257 | J34: =Q48 -> Ba1/BB+ | K34: =S48 -> 0.0696 | L34: =$B$3 -> 0.286 | M34: =K34*(1-L34) -> 0.0496944
D35: 0.8 | E35: =D35/(1-D35) -> 4 | F35: =$B$7*D35 -> 93927657600 | G35: =$B$8 -> 6548000000 | H35: =F35*$F$24 -> 3.7195352e+09 | I35: =G35/H35 -> 1.760435 | J35: =Q49 -> Ba2/BB | K35: =S49 -> 0.0796 | L35: =$B$3 -> 0.286 | M35: =K35*(1-L35) -> 0.0568344
D36: 0.9 | E36: =D36/(1-D36) -> 9 | F36: =$B$7*D36 -> 105668614800 | G36: =$B$8 -> 6548000000 | H36: =F36*$F$24 -> 4.1844771e+09 | I36: =G36/H36 -> 1.5648311 | J36: =Q50 -> B1/B+ | K36: =S50 -> 0.0946 | L36: =$B$3 -> 0.286 | M36: =K36*(1-L36) -> 0.0675444
E40: Nike´s Cost of Capital Schedule | P40: T Bond Rate | Q40: =B1 -> 0.0396 | R40: German Rates & Bonds - Bloomberg
D41: Debt to Capital Ratio | E41: Cost of Equity | F41: After-tax Cost of Debt | G41: Cost of Capital | P41: Interest Coverage Ratio | Q41: Rating | R41: Spread (%) | S41: Interest Rate (%)
D42: 0 | E42: =H13 -> 0.090961496 | F42: =M27 -> 0.0311304 | G42: =((E42*(100%-D42))+(F42*D42)) -> 0.090961496 | P42: > 8.50 | Q42: Aaa/AAA | R42: 0.004 | S42: =$Q$40+R42 -> 0.0436
D43: 0.1 | E43: =H14 -> 0.095036175 | F43: =M28 -> 0.0311304 | G43: =((E43*(100%-D43))+(F43*D43)) -> 0.088645597 | P43: 6.5 –8.5 | Q43: Aa2/AA | R43: 0.007 | S43: =$Q$40+R43 -> 0.0466
D44: 0.2 | E44: =H15 -> 0.10012952 | F44: =M29 -> 0.0332724 | G44: =((E44*(100%-D44))+(F44*D44)) -> 0.086758099 | P44: 5.5 –6.5 | Q44: A1/A+ | R44: 0.0085 | S44: =$Q$40+R44 -> 0.0481
...

Sheet WACC Approach Under Armour
A1: Risk-Free Rate (Rf) | B1: 0.0396 | C1: T Bond Rate | D1: 10-year U.S. Treasury bond yield 1990-2023 | Statista
A2: Market Risk Premium (Rm - Rf) | B2: 0.057 | D2: Average market risk premium Germany 2023 | Statista
A3: Marginal Tax Rate | B3: =21%+8.25% -> 0.2925 | C3: 2024 State Corporate Income Tax Rates & Brackets
A4: Levered Beta (βL) | B4: 1.66 | I4: adidas AG (ADS.DE) Stock Price, News, Quote & History - Yahoo Finance
A5: Unlevered Beta (βU) | B5: =Q6 -> 1.1241818 | P5: Step-2
A6: Total Debt (D) | B6: =Competitors!P175 -> 2607448000 | P6: Unlevered beta | Q6: =B4/(1+(1-B3)*(B6/B7)) -> 1.1241818
A7: Total Equity € | B7: =Dividend!O25*Competitors!P43 -> 3.870448e+09 | C7: As of Dec 2023 | D7: adidas AG (ADS.DE) Stock Historical Prices & Data - Yahoo Finance
A8: EBIT | B8: =Competitors!P51 -> 234179000
A9: EBIT Interest Coverage Ratio | B9: =Ratios!G32 -> 52.885953
A10: Pre-Tax Cost of Debt | G10: Step-3
F11: Estimate Cost of Equity
E12: Debt to Capital Ratio | F12: D/E Ratio | G12: Levered Beta | H12: Cost of Equity
A13: =B6/(B6+B7) -> 0.40251465 | B13: =A13+1 -> 1.4025146 | E13: 0 | F13: =E13/(1-E13) -> 0 | G13: =$Q$6*(1+(1-$B$3)*(F13)) -> 1.1241818 | H13: =$B$1+G13*$B$2 -> 0.10367836
E14: 0.1 | F14: =E14/(1-E14) -> 0.11111111 | G14: =$Q$6*(1+(1-$B$3)*(F14)) -> 1.212555 | H14: =$B$1+G14*$B$2 -> 0.10871564
E15: 0.2 | F15: =E15/(1-E15) -> 0.25 | G15: =$Q$6*(1+(1-$B$3)*(F15)) -> 1.3230215 | H15: =$B$1+G15*$B$2 -> 0.11501223
E16: 0.3 | F16: =E16/(1-E16) -> 0.42857143 | G16: =$Q$6*(1+(1-$B$3)*(F16)) -> 1.4650498 | H16: =$B$1+G16*$B$2 -> 0.12310784
E17: 0.4 | F17: =E17/(1-E17) -> 0.66666667 | G17: =$Q$6*(1+(1-$B$3)*(F17)) -> 1.6544209 | H17: =$B$1+G17*$B$2 -> 0.13390199
E18: 0.5 | F18: =E18/(1-E18) -> 1 | G18: =$Q$6*(1+(1-$B$3)*(F18)) -> 1.9195405 | H18: =$B$1+G18*$B$2 -> 0.14901381
E19: 0.6 | F19: =E19/(1-E19) -> 1.5 | G19: =$Q$6*(1+(1-$B$3)*(F19)) -> 2.3172198 | H19: =$B$1+G19*$B$2 -> 0.17168153
E20: 0.7 | F20: =E20/(1-E20) -> 2.3333333 | G20: =$Q$6*(1+(1-$B$3)*(F20)) -> 2.9800187 | H20: =$B$1+G20*$B$2 -> 0.20946106
E21: 0.8 | F21: =E21/(1-E21) -> 4 | G21: =$Q$6*(1+(1-$B$3)*(F21)) -> 4.3056164 | H21: =$B$1+G21*$B$2 -> 0.28502014
E22: 0.9 | F22: =E22/(1-E22) -> 9 | G22: =$Q$6*(1+(1-$B$3)*(F22)) -> 8.2824097 | H22: =$B$1+G22*$B$2 -> 0.51169735
E24: Risk free rate | F24: =B1 -> 0.0396
E25: Estimate Cost of Debts
D26: Debt to Capital Ratio | E26: D/E Ratio | F26: Debt | G26: EBIT | H26: Interest | I26: Pre-Tax Int. Cov | J26: Likely Rating | K26: Pre-Tax cost of debt | L26: Tax Rate | M26: After Tax Cost of Debt
D27: 0 | E27: =D27/(1-D27) -> 0 | F27: =$B$7*D27 -> 0 | G27: =$B$8 -> 234179000 | H27: =F27*$F$24 -> 0 | I27: =G27/H27 -> #DIV/0! | J27: =R39 -> Aaa/AAA | K27: =T39 -> 0.0436 | L27: =$B$3 -> 0.2925 | M27: =K27*(1-L27) -> 0.030847
D28: 0.1 | E28: =D28/(1-D28) -> 0.11111111 | F28: =$B$7*D28 -> 387044796 | G28: =$B$8 -> 234179000 | H28: =F28*$F$24 -> 15326974 | I28: =G28/H28 -> 15.27888 | J28: =R39 -> Aaa/AAA | K28: =T39 -> 0.0436 | L28: =$B$3 -> 0.2925 | M28: =K28*(1-L28) -> 0.030847
D29: 0.2 | E29: =D29/(1-D29) -> 0.25 | F29: =$B$7*D29 -> 774089592 | G29: =$B$8 -> 234179000 | H29: =F29*$F$24 -> 30653948 | I29: =G29/H29 -> 7.6394402 | J29: =R39 -> Aaa/AAA | K29: =T39 -> 0.0436 | L29: =$B$3 -> 0.2925 | M29: =K29*(1-L29) -> 0.030847
D30: 0.3 | E30: =D30/(1-D30) -> 0.42857143 | F30: =$B$7*D30 -> 1.1611344e+09 | G30: =$B$8 -> 234179000 | H30: =F30*$F$24 -> 45980922 | I30: =G30/H30 -> 5.0929601 | J30: =R41 -> A1/A+ | K30: =T41 -> 0.0481 | L30: =$B$3 -> 0.2925 | M30: =K30*(1-L30) -> 0.03403075
D31: 0.4 | E31: =D31/(1-D31) -> 0.66666667 | F31: =$B$7*D31 -> 1548179184 | G31: =$B$8 -> 234179000 | H31: =F31*$F$24 -> 61307896 | I31: =G31/H31 -> 3.8197201 | J31: =R42 -> A2/A | K31: =T42 -> 0.0496 | L31: =$B$3 -> 0.2925 | M31: =K31*(1-L31) -> 0.035092
D32: 0.5 | E32: =D32/(1-D32) -> 1 | F32: =$B$7*D32 -> 1.935224e+09 | G32: =$B$8 -> 234179000 | H32: =F32*$F$24 -> 76634870 | I32: =G32/H32 -> 3.0557761 | J32: =R43 -> A3/A- | K32: =T43 -> 0.0526 | L32: =$B$3 -> 0.2925 | M32: =K32*(1-L32) -> 0.0372145
D33: 0.6 | E33: =D33/(1-D33) -> 1.5 | F33: =$B$7*D33 -> 2.3222688e+09 | G33: =$B$8 -> 234179000 | H33: =F33*$F$24 -> 91961844 | I33: =G33/H33 -> 2.5464801 | J33: =R43 -> A3/A- | K33: =T43 -> 0.0526 | L33: =$B$3 -> 0.2925 | M33: =K33*(1-L33) -> 0.0372145
D34: 0.7 | E34: =D34/(1-D34) -> 2.3333333 | F34: =$B$7*D34 -> 2.7093136e+09 | G34: =$B$8 -> 234179000 | H34: =F34*$F$24 -> 1.0728882e+08 | I34: =G34/H34 -> 2.1826972 | J34: =R44 -> Baa2/BBB | K34: =T44 -> 0.0596 | L34: =$B$3 -> 0.2925 | M34: =K34*(1-L34) -> 0.042167
D35: 0.8 | E35: =D35/(1-D35) -> 4 | F35: =$B$7*D35 -> 3096358368 | G35: =$B$8 -> 234179000 | H35: =F35*$F$24 -> 1.2261579e+08 | I35: =G35/H35 -> 1.90986 | J35: =R45 -> Ba1/BB+ | K35: =T45 -> 0.0696 | L35: =$B$3 -> 0.2925 | M35: =K35*(1-L35) -> 0.049242
D36: 0.9 | E36: =D36/(1-D36) -> 9 | F36: =$B$7*D36 -> 3.4834032e+09 | G36: =$B$8 -> 234179000 | H36: =F36*$F$24 -> 1.3794277e+08 | I36: =G36/H36 -> 1.6976534 | J36: =R46 -> Ba2/BB | K36: =T46 -> 0.0796 | L36: =$B$3 -> 0.2925 | M36: =K36*(1-L36) -> 0.056317
Q37: T Bond Rate | R37: =B1 -> 0.0396
Q38: Interest Coverage Ratio | R38: Rating | S38: Spread (%) | T38: Interest Rate (%)
Q39: > 8.50 | R39: Aaa/AAA | S39: 0.004 | T39: =$R$37+S39 -> 0.0436
E40: Under Armour´s Cost of Capital Schedule | Q40: 6.5 –8.5 | R40: Aa2/AA | S40: 0.007 | T40: =$R$37+S40 -> 0.0466
D41: Debt to Capital Ratio | E41: Cost of Equity | F41: After-tax Cost of Debt | G41: Cost of Capital | Q41: 5.5 –6.5 | R41: A1/A+ | S41: 0.0085 | T41: =$R$37+S41 -> 0.0481
...

Sheet ⛔️WACC Approach Puma
A1: Risk-Free Rate (Rf) | B1: ='Credit Rating'!C43 -> 0.0248 | C1: T Bond Rate
A2: Market Risk Premium (Rm - Rf) | B2: 0.057 | C2: https://www.statista.com/statistics/664825/average-market-risk-premium-germany-europe/
A3: Marginal Tax Rate | B3: 0.3 | C3: spglobal
A4: Levered Beta (βL) | B4: 1.08 | C4: https://finance.yahoo.com/quote/PBYI/
A5: Unlevered Beta (βU) | B5: =Q6 -> 0.76014188 | P5: Step-2
A6: Total Debt (D) | B6: =Competitors!AA207 -> 4058100000 | P6: Unlevered beta | Q6: =B4/(1+(1-B3)*(B6/B7)) -> 0.76014188
A7: Total Equity € | B7: =Dividend!O26*Competitors!AA64 -> 6.7508439e+09 | C7: As of Dec 2023
A8: EBIT | B8: =Competitors!AA73 -> 715800000
A10: Pre-Tax Cost of Debt | G10: Step-3
F11: Estimate Cost of Equity
E12: Debt to Capital Ratio | F12: D/E Ratio | G12: Levered Beta | H12: Cost of Equity
A13: =B6/(B6+B7) -> 0.37543908 | E13: 0 | F13: =E13/(1-E13) -> 0 | G13: =$Q$6*(1+(1-$B$3)*(F13)) -> 0.76014188 | H13: =$B$1+G13*$B$2 -> 0.068128087
E14: 0.1 | F14: =E14/(1-E14) -> 0.11111111 | G14: =$Q$6*(1+(1-$B$3)*(F14)) -> 0.81926403 | H14: =$B$1+G14*$B$2 -> 0.07149805
E15: 0.2 | F15: =E15/(1-E15) -> 0.25 | G15: =$Q$6*(1+(1-$B$3)*(F15)) -> 0.89316671 | H15: =$B$1+G15*$B$2 -> 0.075710502
E16: 0.3 | F16: =E16/(1-E16) -> 0.42857143 | G16: =$Q$6*(1+(1-$B$3)*(F16)) -> 0.98818444 | H16: =$B$1+G16*$B$2 -> 0.081126513
E17: 0.4 | F17: =E17/(1-E17) -> 0.66666667 | G17: =$Q$6*(1+(1-$B$3)*(F17)) -> 1.1148748 | H17: =$B$1+G17*$B$2 -> 0.088347861
E18: 0.5 | F18: =E18/(1-E18) -> 1 | G18: =$Q$6*(1+(1-$B$3)*(F18)) -> 1.2922412 | H18: =$B$1+G18*$B$2 -> 0.098457748
E19: 0.6 | F19: =E19/(1-E19) -> 1.5 | G19: =$Q$6*(1+(1-$B$3)*(F19)) -> 1.5582909 | H19: =$B$1+G19*$B$2 -> 0.11362258
E20: 0.7 | F20: =E20/(1-E20) -> 2.3333333 | G20: =$Q$6*(1+(1-$B$3)*(F20)) -> 2.001707 | H20: =$B$1+G20*$B$2 -> 0.1388973
E21: 0.8 | F21: =E21/(1-E21) -> 4 | G21: =$Q$6*(1+(1-$B$3)*(F21)) -> 2.8885391 | H21: =$B$1+G21*$B$2 -> 0.18944673
E22: 0.9 | F22: =E22/(1-E22) -> 9 | G22: =$Q$6*(1+(1-$B$3)*(F22)) -> 5.5490357 | H22: =$B$1+G22*$B$2 -> 0.34109504
E24: Pre-Tax Cost of Debt | F24: =B1 -> 0.0248
E25: Estimate Cost of Debts
D26: Debt to Capital Ratio | E26: D/E Ratio | F26: Debt | G26: EBIT | H26: Interest | I26: Pre-Tax Int. Cov | J26: Likely Rating | K26: Pre-Tax cost of debt | L26: Tax Rate | M26: After Tax Cost of Debt
D27: 0 | E27: =D27/(1-D27) -> 0 | F27: =$B$7*D27 -> 0 | G27: =$B$8 -> 715800000 | H27: =F27*$F$24 -> 0 | I27: =G27/H27 -> #DIV/0! | J27: =S41 -> Aaa/AAA | K27: =U41 -> 0.0288 | L27: =$B$3 -> 0.3 | M27: =K27*(1-L27) -> 0.02016
D28: 0.1 | E28: =D28/(1-D28) -> 0.11111111 | F28: =$B$7*D28 -> 6.7508439e+08 | G28: =$B$8 -> 715800000 | H28: =F28*$F$24 -> 16742093 | I28: =G28/H28 -> 42.754511 | J28: =S41 -> Aaa/AAA | K28: =U41 -> 0.0288 | L28: =$B$3 -> 0.3 | M28: =K28*(1-L28) -> 0.02016
D29: 0.2 | E29: =D29/(1-D29) -> 0.25 | F29: =$B$7*D29 -> 1.3501688e+09 | G29: =$B$8 -> 715800000 | H29: =F29*$F$24 -> 33484186 | I29: =G29/H29 -> 21.377256 | J29: =S41 -> Aaa/AAA | K29: =U41 -> 0.0288 | L29: =$B$3 -> 0.3 | M29: =K29*(1-L29) -> 0.02016
D30: 0.3 | E30: =D30/(1-D30) -> 0.42857143 | F30: =$B$7*D30 -> 2.0252532e+09 | G30: =$B$8 -> 715800000 | H30: =F30*$F$24 -> 50226279 | I30: =G30/H30 -> 14.251504 | J30: =S41 -> Aaa/AAA | K30: =U41 -> 0.0288 | L30: =$B$3 -> 0.3 | M30: =K30*(1-L30) -> 0.02016
D31: 0.4 | E31: =D31/(1-D31) -> 0.66666667 | F31: =$B$7*D31 -> 2.7003376e+09 | G31: =$B$8 -> 715800000 | H31: =F31*$F$24 -> 66968372 | I31: =G31/H31 -> 10.688628 | J31: =S41 -> Aaa/AAA | K31: =U41 -> 0.0288 | L31: =$B$3 -> 0.3 | M31: =K31*(1-L31) -> 0.02016
D32: 0.5 | E32: =D32/(1-D32) -> 1 | F32: =$B$7*D32 -> 3.375422e+09 | G32: =$B$8 -> 715800000 | H32: =F32*$F$24 -> 83710464 | I32: =G32/H32 -> 8.5509023 | J32: =S41 -> Aaa/AAA | K32: =U41 -> 0.0288 | L32: =$B$3 -> 0.3 | M32: =K32*(1-L32) -> 0.02016
D33: 0.6 | E33: =D33/(1-D33) -> 1.5 | F33: =$B$7*D33 -> 4.0505063e+09 | G33: =$B$8 -> 715800000 | H33: =F33*$F$24 -> 1.0045256e+08 | I33: =G33/H33 -> 7.1257519 | J33: =S42 -> Aa2/AA | K33: =U42 -> 0.0318 | L33: =$B$3 -> 0.3 | M33: =K33*(1-L33) -> 0.02226
D34: 0.7 | E34: =D34/(1-D34) -> 2.3333333 | F34: =$B$7*D34 -> 4.7255907e+09 | G34: =$B$8 -> 715800000 | H34: =F34*$F$24 -> 1.1719465e+08 | I34: =G34/H34 -> 6.1077873 | J34: =S43 -> A1/A+ | K34: =U43 -> 0.0333 | L34: =$B$3 -> 0.3 | M34: =K34*(1-L34) -> 0.02331
D35: 0.8 | E35: =D35/(1-D35) -> 4 | F35: =$B$7*D35 -> 5.4006751e+09 | G35: =$B$8 -> 715800000 | H35: =F35*$F$24 -> 1.3393674e+08 | I35: =G35/H35 -> 5.3443139 | J35: =S44 -> A2/A | K35: =U44 -> 0.0348 | L35: =$B$3 -> 0.3 | M35: =K35*(1-L35) -> 0.02436
D36: 0.9 | E36: =D36/(1-D36) -> 9 | F36: =$B$7*D36 -> 6.0757595e+09 | G36: =$B$8 -> 715800000 | H36: =F36*$F$24 -> 1.5067884e+08 | I36: =G36/H36 -> 4.7505013 | J36: =S44 -> A2/A | K36: =U44 -> 0.0348 | L36: =$B$3 -> 0.3 | M36: =K36*(1-L36) -> 0.02436
R39: T Bond Rate | S39: =B1 -> 0.0248 | T39: German Rates & Bonds - Bloomberg
E40: Puma´s Cost of Capital Schedule | R40: Interest Coverage Ratio | S40: Rating | T40: Spread (%) | U40: Interest Rate (%)
D41: Debt to Capital Ratio | E41: Cost of Equity | F41: After-tax Cost of Debt | G41: Cost of Capital | R41: > 8.50 | S41: Aaa/AAA | T41: 0.004 | U41: =$S$39+T41 -> 0.0288
D42: 0 | E42: =H13 -> 0.068128087 | F42: =M27 -> 0.02016 | G42: =((E42*(100%-D42))+(F42*D42)) -> 0.068128087 | R42: 6.5 –8.5 | S42: Aa2/AA | T42: 0.007 | U42: =$S$39+T42 -> 0.0318
D43: 0.1 | E43: =H14 -> 0.07149805 | F43: =M28 -> 0.02016 | G43: =((E43*(100%-D43))+(F43*D43)) -> 0.066364245 | R43: 5.5 –6.5 | S43: A1/A+ | T43: 0.0085 | U43: =$S$39+T43 -> 0.0333
D44: 0.2 | E44: =H15 -> 0.075710502 | F44: =M29 -> 0.02016 | G44: =((E44*(100%-D44))+(F44*D44)) -> 0.064600402 | R44: 4.25 –5.5 | S44: A2/A | T44: 0.01 | U44: =$S$39+T44 -> 0.0348
...

Sheet WACC Approach Adidas
A1: Risk-Free Rate (Rf) | B1: ='Credit Rating'!C43 -> 0.0248 | C1: T Bond Rate
A2: Market Risk Premium (Rm - Rf) | B2: 0.057 | C2: https://www.statista.com/statistics/664825/average-market-risk-premium-germany-europe/
A3: Marginal Tax Rate | B3: 0.3 | C3: spglobal
A4: Levered Beta (βL) | B4: 1.16 | I4: adidas AG (ADS.DE) Stock Price, News, Quote & History - Yahoo Finance
A5: Unlevered Beta (βU) | B5: =Q6 -> 0.82691984 | P5: Step-2
A6: Total Debt (D) | B6: =ADDDF!F73 -> 13095000000 | P6: Unlevered beta | Q6: =B4/(1+(1-B3)*(B6/B7)) -> 0.82691984
A7: Value of equity based on market | B7: =Dividend!N23*'Income Statement'!F69 -> 2.2757167e+10 | C7: As of Dec 2023 | D7: adidas AG (ADS.DE) Stock Historical Prices & Data - Yahoo Finance
A8: EBIT | B8: ='Income Statement'!F85 -> 442000000
A9: EBIT Interest Coverage Ratio | B9: =Ratios!G11 -> 2.7116564
A10: Pre-Tax Cost of Debt | G10: Step-3
C11: =B7/Dividend!O23 -> 1.235728e+08 | F11: Estimate Cost of Equity
E12: Debt to Capital Ratio | F12: D/E Ratio | G12: Levered Beta | H12: Cost of Equity
A13: =B6/(B6+B7) -> 0.36524989 | E13: 0 | F13: =E13/(1-E13) -> 0 | G13: =$Q$6*(1+(1-$B$3)*(F13)) -> 0.82691984 | H13: =$B$1+G13*$B$2 -> 0.071934431
E14: 0.1 | F14: =E14/(1-E14) -> 0.11111111 | G14: =$Q$6*(1+(1-$B$3)*(F14)) -> 0.89123583 | H14: =$B$1+G14*$B$2 -> 0.075600442
E15: 0.2 | F15: =E15/(1-E15) -> 0.25 | G15: =$Q$6*(1+(1-$B$3)*(F15)) -> 0.97163081 | H15: =$B$1+G15*$B$2 -> 0.080182956
A16: Free Cash flow to firm | B16: =B8*(1-B3)+'Cash Flow Statement'!F7-(-'Cash Flow Statement'!F31-'Cash Flow Statement'!F34-'Cash Flow Statement'!F37-'Cash Flow Statement'!F40)-0 -> 964400000 | E16: 0.3 | F16: =E16/(1-E16) -> 0.42857143 | G16: =$Q$6*(1+(1-$B$3)*(F16)) -> 1.0749958 | H16: =$B$1+G16*$B$2 -> 0.08607476
A17: Wacc | B17: =(B19*((Dividend!O23*'Income Statement'!F69)/(B6+(Dividend!O23*'Income Statement'!F69))))+B20*(B6/(B6+(Dividend!O23*'Income Statement'!F69))) -> 0.072560176 | E17: 0.4 | F17: =E17/(1-E17) -> 0.66666667 | G17: =$Q$6*(1+(1-$B$3)*(F17)) -> 1.2128158 | H17: =$B$1+G17*$B$2 -> 0.093930499
A18: Current enterprize value | B18: =B7+B6-B16 -> 3.4887767e+10 | E18: 0.5 | F18: =E18/(1-E18) -> 1 | G18: =$Q$6*(1+(1-$B$3)*(F18)) -> 1.4057637 | H18: =$B$1+G18*$B$2 -> 0.10492853
A19: Cost of Equity | B19: =B1+B4*B2 -> 0.09092 | E19: 0.6 | F19: =E19/(1-E19) -> 1.5 | G19: =$Q$6*(1+(1-$B$3)*(F19)) -> 1.6951857 | H19: =$B$1+G19*$B$2 -> 0.12142558
